Workbook

Sheet DPA
F2: RENCANA KERJA DAN ANGGARAN | S2: Formulir RKA - SKPD 2.2.1
F3: SATUAN KERJA PERANGKAT DAERAH
F4: PEMERINTAH PROVINSI BALI
F5: TAHUN ANGGARAN 2026
B6: URUSAN PEMERINTAH | H6: : | I6: 2 - URUSAN PEMERINTAHAN WAJIB YANG TIDAK BERKAITAN DENGAN PELAYANAN DASAR
B7: ORGANISASI | F7: : | G7: 2.16.2.20.2.21.02.0000 - Dinas Komunikasi, Informatika dan Statistik
B8: Program | F8: : | G8: 2.21.02 - PROGRAM PENYELENGGARAAN PERSANDIAN UNTUK PENGAMANAN INFORMASI
B9: Kegiatan | F9: : | G9: 2.21.02.1.02 - PENETAPAN POLA HUBUNGAN KOMUNIKASI SANDI ANTAR PERANGKAT DAERAH PROVINSI
B10: Lokasi Kegiatan | F10: : | G10: Semua Kabupaten / Kota, Semua Kecamatan, Semua Kelurahan
B11: Jumlah Tahun n-1 | F11: : | G11: Rp0,00
B12: Jumlah Tahun n | F12: : | G12: Rp94.371.800,00
B13: Jumlah Tahun n + 1 | F13: : | G13: Rp208.604.000,00
B14: Indikator & Tolok Ukur Kinerja Belanja Langsung
B15: Indikator | F15: Tolok Ukur Kegiatan | R15: Target Kinerja
B16: Capaian Program | G16: Nilai Indeks KAMI | R16: 551 Nilai
B17: Masukan | G17: Dana Yang Dibutuhkan | R17: Rp94.371.800,00
B18: Keluaran | G18: Jumlah Operasionalisasi Layanan Keamanan Informasi dan Persandian Pemerintah Daerah berdasarkan pemetaan pola hubungan komunikasi sandi pemerintah Daerah. | R18: 1 Kegiatan
G20: Printer | R20: 10 unit
G21: Laptop | R21: 13 unit
G22: AC | R22: 15 unit
B24: Hasil | F24: Jumlah entitas jaring komunikasi Pemerintah Provinsi Bali yang terbangun | R24: 29 Perangkat Daerah
B25: Kelompok Sasaran Kegiatan :
B26: Rincian Anggaran Belanja Langsung
B27: Menurut Program dan Per Kegiatan Satuan Kerja Perangkat Daerah
B28: Kode | C28: Uraian | P28: Rincian Perhitungan | S28: Jumlah
B29: Rekening | P29: Volume | Q29: Satuan | R29: Harga Satuan
B30: 1 | C30: 2 | P30: 3 | Q30: 4 | R30: 5 | S30: 6 = ( 3 x 5 )
B31: 5 | C31: BELANJA DAERAH | S31: =S32+S62 -> 94371800
B32: 5.1 | C32: BELANJA OPERASI | S32: =S34 -> 32999400
B34: 5.2.2. | C34: Belanja Barang dan Jasa | S34: =S36+S53 -> 32999400
B36: 5.2.2.01 | C36: Belanja Bahan Pakai Habis | S36: =S38+S43+S47+S50 -> 1791400
B38: 5.1.02.01.01.0024 | C38: Belanja Alat/Bahan untuk Kegiatan Kantor-Alat Tulis Kantor | S38: =SUM(S39:S41) -> 656000
D39: - | E39: Alat Tulis Kantor Spesifikasi : Stof Map Folio | P39: 100 | Q39: Buah | R39: 3300 | S39: =P39*R39 -> 330000
D40: - | E40: Alat Tulis Kantor Spesifikasi : Trigonal Clip No. 5 Atom | P40: 5 | Q40: Lusin | R40: 13200 | S40: =P40*R40 -> 66000
D41: - | E41: Alat Tulis Kantor Spesifikasi : Box File Jumbo Bantex | P41: 5 | Q41: Buah | R41: 52000 | S41: =P41*R41 -> 260000
B43: 5.1.02.01.01.0025 | C43: Belanja Alat/Bahan untuk Kegiatan Kantor- Kertas dan Cover | S43: =SUM(S44:S45) -> 441400
D44: - | E44: Kertas dan Cover Spesifikasi : Kertas HVS A4 70 gr | P44: 2 | Q44: Rim | R44: 82400 | S44: =P44*R44 -> 164800
D45: - | E45: Kertas dan Cover Spesifikasi : Kertas HVS F4 70 gr | P45: 3 | Q45: Rim | R45: 92200 | S45: =P45*R45 -> 276600
B47: 5.1.02.01.01.0026 | C47: Belanja Alat/Bahan untuk Kegiatan Kantor- Bahan Cetak | S47: =S48 -> 544000
D48: - | E48: Foto Copy Spesifikasi : Foto copy Hitam Putih-HVS A4/F4 | P48: 1360 | Q48: Lembar | R48: 400 | S48: =P48*R48 -> 544000
...

Sheet PLGK
B1: RENCANA FISIK DAN KEUANGAN
AH2: =#REF!/#REF! -> #REF! | AI2: =AH2*425000 -> #REF!
AI3: =AH3*425000 -> 0 | BH3: 7350000
BH4: =BH3-#REF! -> #REF!
B5: Kode Rekening | C5: Uraian | G5: Rincian Perhitungan | K5: Bulan Januari | P5: Bulan Pebruari | Y5: Bulan Maret | AH5: Bulan April | AQ5: Bulan Mei | AZ5: Bulan Juni | BI5: Bulan Juli | BR5: Bulan Agustus | CA5: Bulan September | CJ5: Bulan Oktober | CS5: Bulan Nopember | DB5: Bulan Desember | DK5: SISA
K6: Rencana | M6: Realisasi | P6: Rencana | T6: Realisasi | Y6: Rencana | AC6: Realisasi | AH6: Rencana | AL6: Realisasi | AQ6: Rencana | AU6: Realisasi | AZ6: Rencana | BD6: Realisasi | BI6: Rencana | BM6: Realisasi | BR6: Rencana | BV6: Realisasi | CA6: Rencana | CE6: Realisasi | CJ6: Rencana | CN6: Realisasi | CS6: Rencana | CW6: Realisasi | DB6: Rencana | DF6: Realisasi
G7: Volume | I7: Harga Satuan | J7: Jumlah | P7: Bulan Ini | R7: s/d Bulan Ini | T7: Bulan Ini | W7: s/d Bulan Ini | Y7: Bulan Ini | AA7: s/d Bulan Ini | AC7: Bulan Ini | AF7: s/d Bulan Ini | AH7: Bulan Ini | AJ7: s/d Bulan Ini | AL7: Bulan Ini | AO7: s/d Bulan Ini | AQ7: Bulan Ini | AS7: s/d Bulan Ini | AU7: Bulan Ini | AX7: s/d Bulan Ini | AZ7: Bulan Ini | BB7: s/d Bulan Ini | BD7: Bulan Ini | BG7: s/d Bulan Ini | BI7: Bulan Ini | BK7: s/d Bulan Ini | BM7: Bulan Ini | BP7: s/d Bulan Ini | BR7: Bulan Ini | BT7: s/d Bulan Ini | BV7: Bulan Ini | BY7: s/d Bulan Ini | CA7: Bulan Ini | CC7: s/d Bulan Ini | CE7: Bulan Ini | CH7: s/d Bulan Ini | CJ7: Bulan Ini | CL7: s/d Bulan Ini | CN7: Bulan Ini | CQ7: s/d Bulan Ini | CS7: Bulan Ini | CU7: s/d Bulan Ini | CW7: Bulan Ini | CZ7: s/d Bulan Ini | DB7: Bulan Ini | DD7: s/d Bulan Ini | DF7: Bulan Ini | DI7: s/d Bulan Ini | DK7: Volume | DL7: Jumlah
H8: Satuan | K8: Volume | L8: Jumlah | M8: Volume | N8: Harga Satuan | O8: Jumlah | P8: Volume | Q8: Jumlah | R8: Volume | S8: Jumlah | T8: Volume | U8: Harga Satuan | V8: Jumlah | W8: Volume | X8: Jumlah | Y8: Volume | Z8: Jumlah | AA8: Volume | AB8: Jumlah | AC8: Volume | AD8: Harga Satuan | AE8: Jumlah | AF8: Volume | AG8: Jumlah | AH8: Volume | AI8: Jumlah | AJ8: Volume | AK8: Jumlah | AL8: Volume | AM8: Harga Satuan | AN8: Jumlah | AO8: Volume | AP8: Jumlah | AQ8: Volume | AR8: Jumlah | AS8: Volume | AT8: Jumlah | AU8: Volume | AV8: Harga Satuan | AW8: Jumlah | AX8: Volume | AY8: Jumlah | AZ8: Volume | BA8: Jumlah | BB8: Volume | BC8: Jumlah | BD8: Volume | BE8: Harga Satuan | BF8: Jumlah | BG8: Volume | BH8: Jumlah | BI8: Volume | BJ8: Jumlah | BK8: Volume | BL8: Jumlah | BM8: Volume | BN8: Harga Satuan | BO8: Jumlah | BP8: Volume | BQ8: Jumlah | BR8: Volume | BS8: Jumlah | BT8: Volume | BU8: Jumlah | BV8: Volume | BW8: Harga Satuan | BX8: Jumlah | BY8: Volume | BZ8: Jumlah | CA8: Volume | CB8: Jumlah | CC8: Volume | CD8: Jumlah | CE8: Volume | CF8: Harga Satuan | CG8: Jumlah | CH8: Volume | CI8: Jumlah | CJ8: Volume | CK8: Jumlah | CL8: Volume | CM8: Jumlah | CN8: Volume | CO8: Harga Satuan | CP8: Jumlah | CQ8: Volume | CR8: Jumlah | CS8: Volume | CT8: Jumlah | CU8: Volume | CV8: Jumlah | CW8: Volume | CX8: Harga Satuan | CY8: Jumlah | CZ8: Volume | DA8: Jumlah | DB8: Volume | DC8: Jumlah | DD8: Volume | DE8: Jumlah | DF8: Volume | DG8: Harga Satuan | DH8: Jumlah | DI8: Volume | DJ8: Jumlah
B9: 1 | C9: 2 | G9: 3 | H9: 4 | I9: 4 | J9: 5 | K9: =J9+1 -> 6 | L9: =K9+1 -> 7 | M9: =L9+1 -> 8 | N9: =M9+1 -> 9 | O9: =N9+1 -> 10 | P9: =O9+1 -> 11 | Q9: =P9+1 -> 12 | R9: =Q9+1 -> 13 | ... DL9: =DK9+1 -> 111
B10: 5 | C10: =DPA!C31 -> BELANJA DAERAH | J10: =DPA!S31 -> 94371800
B11: =DPA!B32 -> 5.1 | C11: =DPA!C32 -> BELANJA OPERASI | J11: =DPA!S32 -> 32999400
B13: =DPA!B34 -> 5.2.2. | C13: =DPA!C34 -> Belanja Barang dan Jasa | J13: =DPA!S34 -> 32999400
B15: =DPA!B36 -> 5.2.2.01 | C15: =DPA!C36 -> Belanja Bahan Pakai Habis | J15: =DPA!S36 -> 1791400
B17: =DPA!B38 -> 5.1.02.01.01.0024 | C17: =DPA!C38 -> Belanja Alat/Bahan untuk Kegiatan Kantor-Alat Tulis Kantor | J17: =DPA!S38 -> 656000
D18: =DPA!D39 -> - | E18: =DPA!E39 -> Alat Tulis Kantor Spesifikasi : Stof Map Folio | G18: =DPA!P39 -> 100 | H18: =DPA!Q39 -> Buah | I18: =DPA!R39 -> 3300 | J18: =DPA!S39 -> 330000
D19: =DPA!D40 -> - | E19: =DPA!E40 -> Alat Tulis Kantor Spesifikasi : Trigonal Clip No. 5 Atom | G19: =DPA!P40 -> 5 | H19: =DPA!Q40 -> Lusin | I19: =DPA!R40 -> 13200 | J19: =DPA!S40 -> 66000
D20: =DPA!D41 -> - | E20: =DPA!E41 -> Alat Tulis Kantor Spesifikasi : Box File Jumbo Bantex | G20: =DPA!P41 -> 5 | H20: =DPA!Q41 -> Buah | I20: =DPA!R41 -> 52000 | J20: =DPA!S41 -> 260000
B22: =DPA!B43 -> 5.1.02.01.01.0025 | C22: =DPA!C43 -> Belanja Alat/Bahan untuk Kegiatan Kantor- Kertas dan Cover | J22: =DPA!S43 -> 441400
D23: =DPA!D44 -> - | E23: =DPA!E44 -> Kertas dan Cover Spesifikasi : Kertas HVS A4 70 gr | G23: =DPA!P44 -> 2 | H23: =DPA!Q44 -> Rim | I23: =DPA!R44 -> 82400 | J23: =DPA!S44 -> 164800
D24: =DPA!D45 -> - | E24: =DPA!E45 -> Kertas dan Cover Spesifikasi : Kertas HVS F4 70 gr | G24: =DPA!P45 -> 3 | H24: =DPA!Q45 -> Rim | I24: =DPA!R45 -> 92200 | J24: =DPA!S45 -> 276600
B26: =DPA!B47 -> 5.1.02.01.01.0026 | C26: =DPA!C47 -> Belanja Alat/Bahan untuk Kegiatan Kantor- Bahan Cetak | J26: =DPA!S47 -> 544000
D27: =DPA!D48 -> - | E27: =DPA!E48 -> Foto Copy Spesifikasi : Foto copy Hitam Putih-HVS A4/F4 | G27: =DPA!P48 -> 1360 | H27: =DPA!Q48 -> Lembar | I27: =DPA!R48 -> 400 | J27: =DPA!S48 -> 544000
B29: =DPA!B50 -> 5.1.02.01.01.0027 | C29: =DPA!C50 -> Belanja Alat/Bahan untuk Kegiatan Kantor-Benda Pos | J29: =DPA!S50 -> 150000
D30: =DPA!D51 -> - | E30: =DPA!E51 -> Materai Spesifikasi: Materai 10.000 | G30: =DPA!P51 -> 15 | H30: =DPA!Q51 -> Lembar | I30: =DPA!R51 -> 10000 | J30: =DPA!S51 -> 150000
B32: =DPA!B53 -> 5.1.02.04 | C32: =DPA!C53 -> Belanja Perjalanan Dinas | J32: =DPA!S53 -> 31208000
B33: =DPA!B54 -> 5.1.02.04.01 | C33: =DPA!C54 -> Belanja Perjalanan Dinas Dalam Negeri | J33: =DPA!S54 -> 31208000
B34: =DPA!B55 -> 5.1.02.04.01.0001 | C34: =DPA!C55 -> Belanja Perjalanan Dinas Biasa | J34: =DPA!S55 -> 31208000
D35: - | E35: =DPA!E56 -> Penginapan Dalam Negeri di- D.K.I. JAKARTA Spesifikasi: PEJABAT ESELON III / GOLONGAN IV | G35: =DPA!P56 -> 8 | H35: =DPA!Q56 -> Orang / Hari | I35: =DPA!R56 -> 992000 | J35: =DPA!S56 -> 7936000
D36: - | E36: =DPA!E57 -> Taxi dari/ke Bandara - Perjalanan Dinas Dalam Negeri Spesifikasi: BALI | G36: =DPA!P57 -> 8 | H36: =DPA!Q57 -> Orang / Kali | I36: =DPA!R57 -> 227000 | J36: =DPA!S57 -> 1816000
D37: - | E37: =DPA!E58 -> Taxi dari/ke Bandara - Perjalanan Dinas Dalam Negeri Spesifikasi: D.K.I. JAKARTA | G37: =DPA!P58 -> 8 | H37: =DPA!Q58 -> Orang / Kali | I37: =DPA!R58 -> 256000 | J37: =DPA!S58 -> 2048000
D38: - | E38: =DPA!E59 -> Satuan Biaya Tiket Dalam Negeri Spesifikasi : Denpasar - Jakarta | G38: =DPA!P59 -> 4 | H38: =DPA!Q59 -> Orang /PP | I38: =DPA!R59 -> 3262000 | J38: =DPA!S59 -> 13048000
D39: - | E39: =DPA!E60 -> Uang Harian Perjalanan Dinas Luar Kota/Luar Daerah Spesifikasi: D.K.I. JAKARTA | G39: =DPA!P60 -> 12 | H39: =DPA!Q60 -> Orang / Hari | I39: =DPA!R60 -> 530000 | J39: =DPA!S60 -> 6360000
B41: =DPA!B62 -> 5.2 | C41: =DPA!C62 -> Belanja Modal | J41: =DPA!S62 -> 61372400
B42: =DPA!B63 -> 5.2.02 | C42: =DPA!C63 -> Belanja Modal Perapatan dan Mesin | J42: =DPA!S63 -> 61372400
B43: =DPA!B64 -> 5.2.02.05 | C43: =DPA!C64 -> Belanja Modal Alat Kantor dan Rumah Tangga | J43: =DPA!S64 -> 61372400
B44: =DPA!B65 -> 5.2.02.05.001 | C44: =DPA!C65 -> Belanja Modal Alat Kantor | J44: =DPA!S65 -> 34347600
B45: =DPA!B66 -> 5.2.02.05.001.00005 | C45: =DPA!C66 -> Belanja Modal Alat Kantor Lainnya | J45: =DPA!S66 -> 34347600
D46: =DPA!D67 -> - | E46: =DPA!E67 -> Peralatan Studio Video dan Film Spesifikasi : Kamera Foto (SONY A7 IV BODY + LENSA ZOOM 28-70MM) | I46: =DPA!R67 -> 34347600 | J46: =DPA!S67 -> 34347600
B48: =DPA!B69 -> 5.2.02.05.002 | C48: =DPA!C69 -> Belanja Modal Alat Rumah Tangga | J48: =DPA!S69 -> 27024800
B49: =DPA!B70 -> 5.2.02.05.002.000 06 | C49: =DPA!C70 -> Belanja Modal Alat Rumah Tangga Lainnya (Home Use) | J49: =DPA!S70 -> 27024800
...

Sheet Bobot
B3: Kode Rekening | C3: Uraian | G3: Rincian Perhitungan | K3: Bulan Januari | P3: Bulan Pebruari | Y3: Bulan Maret | AH3: Bulan April | AQ3: Bulan Mei | AZ3: Bulan Juni | BI3: Bulan Juli | BR3: Bulan Agustus | CA3: Bulan September | CJ3: Bulan Oktober | CS3: Bulan Nopember | DB3: Bulan Desember | DK3: SISA
K4: Rencana | M4: Realisasi | P4: Rencana | T4: Realisasi | Y4: Rencana | AC4: Realisasi | AH4: Rencana | AL4: Realisasi | AQ4: Rencana | AU4: Realisasi | AZ4: Rencana | BD4: Realisasi | BI4: Rencana | BM4: Realisasi | BR4: Rencana | BV4: Realisasi | CA4: Rencana | CE4: Realisasi | CJ4: Rencana | CN4: Realisasi | CS4: Rencana | CW4: Realisasi | DB4: Rencana | DF4: Realisasi
G5: Volume | H5: Satuan | I5: Harga Satuan | J5: Jumlah | P5: Bulan Ini | R5: s/d Bulan Ini | T5: Bulan Ini | W5: s/d Bulan Ini | Y5: Bulan Ini | AA5: s/d Bulan Ini | AC5: Bulan Ini | AF5: s/d Bulan Ini | AH5: Bulan Ini | AJ5: s/d Bulan Ini | AL5: Bulan Ini | AO5: s/d Bulan Ini | AQ5: Bulan Ini | AS5: s/d Bulan Ini | AU5: Bulan Ini | AX5: s/d Bulan Ini | AZ5: Bulan Ini | BB5: s/d Bulan Ini | BD5: Bulan Ini | BG5: s/d Bulan Ini | BI5: Bulan Ini | BK5: s/d Bulan Ini | BM5: Bulan Ini | BP5: s/d Bulan Ini | BR5: Bulan Ini | BT5: s/d Bulan Ini | BV5: Bulan Ini | BY5: s/d Bulan Ini | CA5: Bulan Ini | CC5: s/d Bulan Ini | CE5: Bulan Ini | CH5: s/d Bulan Ini | CJ5: Bulan Ini | CL5: s/d Bulan Ini | CN5: Bulan Ini | CQ5: s/d Bulan Ini | CS5: Bulan Ini | CU5: s/d Bulan Ini | CW5: Bulan Ini | CZ5: s/d Bulan Ini | DB5: Bulan Ini | DD5: s/d Bulan Ini | DF5: Bulan Ini | DI5: s/d Bulan Ini | DK5: Volume | DL5: Jumlah
K6: Volume | L6: Jumlah | M6: Volume | N6: Harga Satuan | O6: Jumlah | P6: Volume | Q6: Jumlah | R6: Volume | S6: Jumlah | T6: Volume | U6: Harga Satuan | V6: Jumlah | W6: Volume | X6: Jumlah | Y6: Volume | Z6: Jumlah | AA6: Volume | AB6: Jumlah | AC6: Volume | AD6: Harga Satuan | AE6: Jumlah | AF6: Volume | AG6: Jumlah | AH6: Volume | AI6: Jumlah | AJ6: Volume | AK6: Jumlah | AL6: Volume | AM6: Harga Satuan | AN6: Jumlah | AO6: Volume | AP6: Jumlah | AQ6: Volume | AR6: Jumlah | AS6: Volume | AT6: Jumlah | AU6: Volume | AV6: Harga Satuan | AW6: Jumlah | AX6: Volume | AY6: Jumlah | AZ6: Volume | BA6: Jumlah | BB6: Volume | BC6: Jumlah | BD6: Volume | BE6: Harga Satuan | BF6: Jumlah | BG6: Volume | BH6: Jumlah | BI6: Volume | BJ6: Jumlah | BK6: Volume | BL6: Jumlah | BM6: Volume | BN6: Harga Satuan | BO6: Jumlah | BP6: Volume | BQ6: Jumlah | BR6: Volume | BS6: Jumlah | BT6: Volume | BU6: Jumlah | BV6: Volume | BW6: Harga Satuan | BX6: Jumlah | BY6: Volume | BZ6: Jumlah | CA6: Volume | CB6: Jumlah | CC6: Volume | CD6: Jumlah | CE6: Volume | CF6: Harga Satuan | CG6: Jumlah | CH6: Volume | CI6: Jumlah | CJ6: Volume | CK6: Jumlah | CL6: Volume | CM6: Jumlah | CN6: Volume | CO6: Harga Satuan | CP6: Jumlah | CQ6: Volume | CR6: Jumlah | CS6: Volume | CT6: Jumlah | CU6: Volume | CV6: Jumlah | CW6: Volume | CX6: Harga Satuan | CY6: Jumlah | CZ6: Volume | DA6: Jumlah | DB6: Volume | DC6: Jumlah | DD6: Volume | DE6: Jumlah | DF6: Volume | DG6: Harga Satuan | DH6: Jumlah | DI6: Volume | DJ6: Jumlah
B7: 1 | C7: 2 | G7: 3 | H7: 4 | I7: 5 | J7: 4 | K7: 5 | L7: 6 | M7: 7 | N7: 8 | O7: 9 | P7: 10 | Q7: 11 | R7: =Q7+1 -> 12 | S7: =R7+1 -> 13 | T7: =S7+1 -> 14 | U7: =T7+1 -> 15 | V7: =U7+1 -> 16 | W7: =V7+1 -> 17 | X7: =W7+1 -> 18 | Y7: =X7+1 -> 19 | ... DL7: =DK7+1 -> 110
B8: =PLGK!B10 -> 5 | C8: =PLGK!C10 -> BELANJA DAERAH | J8: =PLGK!J10 -> 94371800
B9: =PLGK!B11 -> 5.1 | C9: =PLGK!C11 -> BELANJA OPERASI | J9: =PLGK!J11 -> 32999400
B11: =PLGK!B13 -> 5.2.2. | C11: =PLGK!C13 -> Belanja Barang dan Jasa | J11: =PLGK!J13 -> 32999400
B13: =PLGK!B15 -> 5.2.2.01 | C13: =PLGK!C15 -> Belanja Bahan Pakai Habis | J13: =PLGK!J15 -> 1791400
B15: =PLGK!B17 -> 5.1.02.01.01.0024 | C15: =PLGK!C17 -> Belanja Alat/Bahan untuk Kegiatan Kantor-Alat Tulis Kantor | J15: =PLGK!J17 -> 656000
D16: =PLGK!D18 -> - | E16: =PLGK!E18 -> Alat Tulis Kantor Spesifikasi : Stof Map Folio | G16: =PLGK!G18 -> 100 | H16: =PLGK!H18 -> Buah | I16: =PLGK!I18 -> 3300 | J16: =PLGK!J18 -> 330000
D17: =PLGK!D19 -> - | E17: =PLGK!E19 -> Alat Tulis Kantor Spesifikasi : Trigonal Clip No. 5 Atom | G17: =PLGK!G19 -> 5 | H17: =PLGK!H19 -> Lusin | I17: =PLGK!I19 -> 13200 | J17: =PLGK!J19 -> 66000
D18: =PLGK!D20 -> - | E18: =PLGK!E20 -> Alat Tulis Kantor Spesifikasi : Box File Jumbo Bantex | G18: =PLGK!G20 -> 5 | H18: =PLGK!H20 -> Buah | I18: =PLGK!I20 -> 52000 | J18: =PLGK!J20 -> 260000
B20: =PLGK!B22 -> 5.1.02.01.01.0025 | C20: =PLGK!C22 -> Belanja Alat/Bahan untuk Kegiatan Kantor- Kertas dan Cover | J20: =PLGK!J22 -> 441400
D21: =PLGK!D23 -> - | E21: =PLGK!E23 -> Kertas dan Cover Spesifikasi : Kertas HVS A4 70 gr | G21: =PLGK!G23 -> 2 | H21: =PLGK!H23 -> Rim | I21: =PLGK!I23 -> 82400 | J21: =PLGK!J23 -> 164800
D22: =PLGK!D24 -> - | E22: =PLGK!E24 -> Kertas dan Cover Spesifikasi : Kertas HVS F4 70 gr | G22: =PLGK!G24 -> 3 | H22: =PLGK!H24 -> Rim | I22: =PLGK!I24 -> 92200 | J22: =PLGK!J24 -> 276600
B24: =PLGK!B26 -> 5.1.02.01.01.0026 | C24: =PLGK!C26 -> Belanja Alat/Bahan untuk Kegiatan Kantor- Bahan Cetak | J24: =PLGK!J26 -> 544000
D25: =PLGK!D27 -> - | E25: =PLGK!E27 -> Foto Copy Spesifikasi : Foto copy Hitam Putih-HVS A4/F4 | G25: =PLGK!G27 -> 1360 | H25: =PLGK!H27 -> Lembar | I25: =PLGK!I27 -> 400 | J25: =PLGK!J27 -> 544000
B27: =PLGK!B29 -> 5.1.02.01.01.0027 | C27: =PLGK!C29 -> Belanja Alat/Bahan untuk Kegiatan Kantor-Benda Pos | J27: =PLGK!J29 -> 150000
D28: =PLGK!D30 -> - | E28: =PLGK!E30 -> Materai Spesifikasi: Materai 10.000 | G28: =PLGK!G30 -> 15 | H28: =PLGK!H30 -> Lembar | I28: =PLGK!I30 -> 10000 | J28: =PLGK!J30 -> 150000
B30: =PLGK!B32 -> 5.1.02.04 | C30: =PLGK!C32 -> Belanja Perjalanan Dinas | J30: =PLGK!J32 -> 31208000
B31: =PLGK!B33 -> 5.1.02.04.01 | C31: =PLGK!C33 -> Belanja Perjalanan Dinas Dalam Negeri | J31: =PLGK!J33 -> 31208000
B32: =PLGK!B34 -> 5.1.02.04.01.0001 | C32: =PLGK!C34 -> Belanja Perjalanan Dinas Biasa | J32: =PLGK!J34 -> 31208000
D33: =PLGK!D35 -> - | E33: =PLGK!E35 -> Penginapan Dalam Negeri di- D.K.I. JAKARTA Spesifikasi: PEJABAT ESELON III / GOLONGAN IV | G33: =PLGK!G35 -> 8 | H33: =PLGK!H35 -> Orang / Hari | I33: =PLGK!I35 -> 992000 | J33: =PLGK!J35 -> 7936000
D34: =PLGK!D36 -> - | E34: =PLGK!E36 -> Taxi dari/ke Bandara - Perjalanan Dinas Dalam Negeri Spesifikasi: BALI | G34: =PLGK!G36 -> 8 | H34: =PLGK!H36 -> Orang / Kali | I34: =PLGK!I36 -> 227000 | J34: =PLGK!J36 -> 1816000
D35: =PLGK!D37 -> - | E35: =PLGK!E37 -> Taxi dari/ke Bandara - Perjalanan Dinas Dalam Negeri Spesifikasi: D.K.I. JAKARTA | G35: =PLGK!G37 -> 8 | H35: =PLGK!H37 -> Orang / Kali | I35: =PLGK!I37 -> 256000 | J35: =PLGK!J37 -> 2048000
D36: =PLGK!D38 -> - | E36: =PLGK!E38 -> Satuan Biaya Tiket Dalam Negeri Spesifikasi : Denpasar - Jakarta | G36: =PLGK!G38 -> 4 | H36: =PLGK!H38 -> Orang /PP | I36: =PLGK!I38 -> 3262000 | J36: =PLGK!J38 -> 13048000
D37: =PLGK!D39 -> - | E37: =PLGK!E39 -> Uang Harian Perjalanan Dinas Luar Kota/Luar Daerah Spesifikasi: D.K.I. JAKARTA | G37: =PLGK!G39 -> 12 | H37: =PLGK!H39 -> Orang / Hari | I37: =PLGK!I39 -> 530000 | J37: =PLGK!J39 -> 6360000
B39: =PLGK!B41 -> 5.2 | C39: =PLGK!C41 -> Belanja Modal | J39: =PLGK!J41 -> 61372400
B40: =PLGK!B42 -> 5.2.02 | C40: =PLGK!C42 -> Belanja Modal Perapatan dan Mesin | J40: =PLGK!J42 -> 61372400
B41: =PLGK!B43 -> 5.2.02.05 | C41: =PLGK!C43 -> Belanja Modal Alat Kantor dan Rumah Tangga | J41: =PLGK!J43 -> 61372400
B42: =PLGK!B44 -> 5.2.02.05.001 | C42: =PLGK!C44 -> Belanja Modal Alat Kantor | J42: =PLGK!J44 -> 34347600
B43: =PLGK!B45 -> 5.2.02.05.001.00005 | C43: =PLGK!C45 -> Belanja Modal Alat Kantor Lainnya | J43: =PLGK!J45 -> 34347600
D44: =PLGK!D46 -> - | E44: =PLGK!E46 -> Peralatan Studio Video dan Film Spesifikasi : Kamera Foto (SONY A7 IV BODY + LENSA ZOOM 28-70MM) | I44: =PLGK!I46 -> 34347600 | J44: =PLGK!J46 -> 34347600
B46: =PLGK!B48 -> 5.2.02.05.002 | C46: =PLGK!C48 -> Belanja Modal Alat Rumah Tangga | J46: =PLGK!J48 -> 27024800
B47: =PLGK!B49 -> 5.2.02.05.002.000 06 | C47: =PLGK!C49 -> Belanja Modal Alat Rumah Tangga Lainnya (Home Use) | J47: =PLGK!J49 -> 27024800
D48: =PLGK!D50 -> - | E48: =PLGK!E50 -> Televisi Spesifikasi : Smart TV 70 Inch min. UHD 4K, Garansi Min. 1 Tahun | I48: =PLGK!I50 -> 27024800 | J48: =PLGK!J50 -> 27024800
B50: Jumlah | J50: =J8 -> 94371800 | L50: =L8 | O50: =O8 | Q50: =Q8 | S50: =S8 | V50: =V8 | X50: =X8 | Z50: =Z8 | AB50: =AB8 | AE50: =AE8 | AG50: =AG8 | AI50: =AI8 | AK50: =AK8 | AN50: =AN8 | AP50: =AP8 | AR50: =AR8 | AT50: =AT8 | AV50: =AV8 | AW50: =AW8 | AY50: =AY8 | BA50: =BA8 | BC50: =BC8 | BF50: =BF8 | BH50: =BH8 | BJ50: =BJ8 | BL50: =BL8 | BO50: =BO8 | BQ50: =BQ8 | BS50: =BS8 | BU50: =BU8 | BX50: =BX8 | BZ50: =BZ8 | CB50: =CB8 | CD50: =CD8 | CG50: =CG8 | CI50: =CI8 | CK50: =CK8 | CM50: =CM8 | CP50: =CP8 | CR50: =CR8 | CT50: =CT8 | CV50: =CV8 | CY50: =CY8 | DA50: =DA8 | DC50: =DC8 | DE50: =DE8 | DH50: =DH8 | DJ50: =DJ8 | DL50: =DL8

Sheet ROK OP
B2: RENCANA OPERASIONAL KEGIATAN (ROK)
B3: KEGIATAN PENYUSUNAN, PERENCANAAN, DAN PELAPORAN CAPAIAN KINERJA
B5: No | C5: Uraian | H5: BIAYA | I5: BULAN
I6: JAN | J6: PEB | K6: MARET | L6: APRIL | M6: MEI | N6: JUNI | O6: JULI | P6: AGUST | Q6: SEPT | R6: OKT | S6: NOV | T6: DES
B7: 1 | C7: 2 | H7: 3 | I7: =H7+1 -> 4 | J7: =I7+1 -> 5 | K7: =J7+1 -> 6 | L7: =K7+1 -> 7 | M7: =L7+1 -> 8 | N7: =M7+1 -> 9 | O7: =N7+1 -> 10 | P7: =O7+1 -> 11 | ... T7: =S7+1 -> 15 | V7: 100
B10: 1 | C10: =PLGK!C17 -> Belanja Alat/Bahan untuk Kegiatan Kantor-Alat Tulis Kantor | H10: =PLGK!J17 -> 656000 | I10: =PLGK!L17 | J10: =PLGK!Q17 | K10: =PLGK!Z17 | L10: =PLGK!AI17 | M10: =PLGK!AR17 | N10: =PLGK!BA17 | O10: =PLGK!BJ17 | P10: =PLGK!BS17 | Q10: =PLGK!CB17 | R10: =PLGK!CK17 | S10: =PLGK!CT17 | T10: =PLGK!DC17
V13: 75
B21: 2 | C21: =PLGK!C22 -> Belanja Alat/Bahan untuk Kegiatan Kantor- Kertas dan Cover | H21: =PLGK!J22 -> 441400 | I21: =PLGK!L22 | J21: =PLGK!Q22 | K21: =PLGK!Z22 | L21: =PLGK!AI22 | M21: =PLGK!AR22 | N21: =PLGK!BA22 | O21: =PLGK!BJ22 | P21: =PLGK!BS22 | Q21: =PLGK!CB22 | R21: =PLGK!CK22 | S21: =PLGK!CT22 | T21: =PLGK!DC22
V25: 75
B32: 3 | C32: =PLGK!C26 -> Belanja Alat/Bahan untuk Kegiatan Kantor- Bahan Cetak | H32: =PLGK!#REF! -> #ERROR! | I32: =PLGK!#REF! -> #ERROR! | J32: =PLGK!#REF! -> #ERROR! | K32: =PLGK!#REF! -> #ERROR! | L32: =PLGK!#REF! -> #ERROR! | M32: =PLGK!#REF! -> #ERROR! | N32: =PLGK!#REF! -> #ERROR! | O32: =PLGK!#REF! -> #ERROR! | ... T32: =PLGK!#REF! -> #ERROR!
B43: 4 | C43: =PLGK!C26 -> Belanja Alat/Bahan untuk Kegiatan Kantor- Bahan Cetak | H43: =PLGK!#REF! -> #ERROR! | I43: =PLGK!#REF! -> #ERROR! | J43: =PLGK!#REF! -> #ERROR! | K43: =PLGK!#REF! -> #ERROR! | L43: =PLGK!#REF! -> #ERROR! | M43: =PLGK!#REF! -> #ERROR! | N43: =PLGK!#REF! -> #ERROR! | O43: =PLGK!#REF! -> #ERROR! | ... T43: =PLGK!#REF! -> #ERROR!
V44: 50
B48: 5 | C48: =PLGK!C29 -> Belanja Alat/Bahan untuk Kegiatan Kantor-Benda Pos | H48: =PLGK!J32 -> 31208000 | I48: =PLGK!L32 | J48: =PLGK!Q32 | K48: =PLGK!Z32 | L48: =PLGK!AI32 | M48: =PLGK!AR32 | N48: =PLGK!BA32 | O48: =PLGK!BJ32 | P48: =PLGK!BS32 | Q48: =PLGK!CB32 | R48: =PLGK!CK32 | S48: =PLGK!CT32 | T48: =PLGK!DC32
B58: 6 | C58: =PLGK!C34 -> Belanja Perjalanan Dinas Biasa | H58: =PLGK!J42 -> 61372400 | I58: =PLGK!L42 | J58: =PLGK!Q42 | K58: =PLGK!Z42 | L58: =PLGK!AI42 | M58: =PLGK!AR42 | N58: =PLGK!BA42 | O58: =PLGK!BJ42 | P58: =PLGK!BS42 | Q58: =PLGK!CB42 | R58: =PLGK!CK42 | S58: =PLGK!CT42 | T58: =PLGK!DC42
V59: 25
B62: 7 | C62: =PLGK!C45 -> Belanja Modal Alat Kantor Lainnya | H62: =PLGK!J46 -> 34347600 | I62: =PLGK!L46 | J62: =PLGK!Q46 | K62: =PLGK!Z46 | L62: =PLGK!AI46 | M62: =PLGK!AR46 | N62: =PLGK!BA46 | O62: =PLGK!BJ46 | P62: =PLGK!BS46 | Q62: =PLGK!CB46 | R62: =PLGK!CK46 | S62: =PLGK!CT46 | T62: =PLGK!DC46
V66: 0
C67: Rencanan Anggaran Per Bulan | H67: =SUM(H9:H66) -> #ERROR! | I67: =SUM(I9:I66) -> #ERROR! | J67: =SUM(J9:J66) -> #ERROR! | K67: =SUM(K9:K66) -> #ERROR! | L67: =SUM(L9:L66) -> #ERROR! | M67: =SUM(M9:M66) -> #ERROR! | N67: =SUM(N9:N66) -> #ERROR! | O67: =SUM(O9:O66) -> #ERROR! | ... T67: =SUM(T9:T66) -> #ERROR!
C68: Akumulasi | I68: =I67 -> #ERROR! | J68: =I68+J67 -> #ERROR! | K68: =J68+K67 -> #ERROR! | L68: =K68+L67 -> #ERROR! | M68: =L68+M67 -> #ERROR! | N68: =M68+N67 -> #ERROR! | O68: =N68+O67 -> #ERROR! | P68: =O68+P67 -> #ERROR! | Q68: =P68+Q67 -> #ERROR! | ... T68: =S68+T67 -> #ERROR!
C69: Rencana Per Tri Wulan | K69: =J68+K67 -> #ERROR! | N69: =SUM(L67:N67) -> #ERROR! | Q69: =SUM(O67:Q67) -> #ERROR! | T69: =SUM(R67:T67) -> #ERROR!
C70: Prosentase per Bulan (%) | I70: =I67/$H$67*100 -> #ERROR! | J70: =J67/$H$67*100 -> #ERROR! | K70: =K67/$H$67*100 -> #ERROR! | L70: =L67/$H$67*100 -> #ERROR! | M70: =M67/$H$67*100 -> #ERROR! | N70: =N67/$H$67*100 -> #ERROR! | O70: =O67/$H$67*100 -> #ERROR! | P70: =P67/$H$67*100 -> #ERROR! | ... T70: =T67/$H$67*100 -> #ERROR!
C71: Akumulasi Prosentase (%) | H71: 0 | I71: =I70 -> #ERROR! | J71: =I71+J70 -> #ERROR! | K71: =J71+K70 -> #ERROR! | L71: =K71+L70 -> #ERROR! | M71: =L71+M70 -> #ERROR! | N71: =M71+N70 -> #ERROR! | O71: =N71+O70 -> #ERROR! | P71: =O71+P70 -> #ERROR! | Q71: =P71+Q70 -> #ERROR! | ... T71: =S71+T70 -> #ERROR!
B72: Fn:C\Pramana\12PemelLGK.xls
P73: Denpasar,
E74: Mengetahui / Menyetujui | P74: Pejabat Pelaksana Teknis Kegiatan
E75: Kepala Dinas Komunikasi
E76: Informatika dan Statistik Provinsi Bali
E80: GEDE PRAMANA, ST, MT
E81: Pembina Utama Madya
E82: NIP. 19680531 199703 1 002

Sheet Jan
B1: LAPORAN REALISASI FISIK DAN KEUANGAN
B2: APBD PROVINSI BALI TAHUN 2026
B4: SKPD | D4: : | M4: PROGRAM
B5: SUB UNIT KERJA | D5: : | M5: KEGIATAN
B6: SUB BAGIAN | D6: : | M6: PPTK
B7: STATUS | D7: :
B9: KODE REKENING | C9: URAIAN BELANJA | F9: RENCANA KEGIATAN | L9: PELAKSANAAN KEGIATAN | T9: SALDO
F10: VOL | G10: SAT | H10: LOKASI | I10: JML PAKET | K10: ANGGARAN | L10: KONTRAK SWAKELOLA | M10: SISA ANGGARAN | N10: PROGRES
N11: FISIK | Q11: KEUANGAN
N12: RENC | O12: REAL | P12: DEV | Q12: RENC | R12: REAL Rp. | S12: %
B13: a | C13: b | F13: c | G13: d | H13: e | I13: f | K13: g | L13: h | M13: i | N13: j | O13: k | P13: l | Q13: m | R13: n | S13: o | T13: p
B14: =DPA!B31 -> 5 | C14: =DPA!C31 -> BELANJA DAERAH | K14: =DPA!S31 -> 94371800 | M14: =K14 -> 94371800
B15: =DPA!B32 -> 5.1 | C15: =DPA!C32 -> BELANJA OPERASI | K15: =DPA!S32 -> 32999400 | M15: =K15 -> 32999400
B17: =DPA!B34 -> 5.2.2. | C17: =DPA!C34 -> Belanja Barang dan Jasa | K17: =DPA!S34 -> 32999400 | M17: =K17 -> 32999400
B19: =DPA!B36 -> 5.2.2.01 | C19: =DPA!C36 -> Belanja Bahan Pakai Habis | K19: =DPA!S36 -> 1791400 | M19: =K19 -> 1791400
B21: =DPA!B38 -> 5.1.02.01.01.0024 | C21: =DPA!C38 -> Belanja Alat/Bahan untuk Kegiatan Kantor-Alat Tulis Kantor | K21: =DPA!S38 -> 656000 | M21: =K21 -> 656000
D22: =DPA!D39 -> - | E22: =DPA!E39 -> Alat Tulis Kantor Spesifikasi : Stof Map Folio | K22: =DPA!S39 -> 330000 | M22: =K22 -> 330000
D23: =DPA!D40 -> - | E23: =DPA!E40 -> Alat Tulis Kantor Spesifikasi : Trigonal Clip No. 5 Atom | K23: =DPA!S40 -> 66000 | M23: =K23 -> 66000
D24: =DPA!D41 -> - | E24: =DPA!E41 -> Alat Tulis Kantor Spesifikasi : Box File Jumbo Bantex | K24: =DPA!S41 -> 260000 | M24: =K24 -> 260000
K25: =DPA!S42 | M25: =K25
B26: =DPA!B43 -> 5.1.02.01.01.0025 | C26: =DPA!C43 -> Belanja Alat/Bahan untuk Kegiatan Kantor- Kertas dan Cover | K26: =DPA!S43 -> 441400 | M26: =K26 -> 441400
D27: =DPA!D44 -> - | E27: =DPA!E44 -> Kertas dan Cover Spesifikasi : Kertas HVS A4 70 gr | K27: =DPA!S44 -> 164800 | M27: =K27 -> 164800
D28: =DPA!D45 -> - | E28: =DPA!E45 -> Kertas dan Cover Spesifikasi : Kertas HVS F4 70 gr | K28: =DPA!S45 -> 276600 | M28: =K28 -> 276600
B30: =DPA!B47 -> 5.1.02.01.01.0026 | C30: =DPA!C47 -> Belanja Alat/Bahan untuk Kegiatan Kantor- Bahan Cetak | K30: =DPA!S47 -> 544000 | M30: =K30 -> 544000
D31: =DPA!D48 -> - | E31: =DPA!E48 -> Foto Copy Spesifikasi : Foto copy Hitam Putih-HVS A4/F4 | K31: =DPA!S48 -> 544000 | M31: =K31 -> 544000
B33: =DPA!B50 -> 5.1.02.01.01.0027 | C33: =DPA!C50 -> Belanja Alat/Bahan untuk Kegiatan Kantor-Benda Pos | K33: =DPA!S50 -> 150000 | M33: =K33 -> 150000
D34: =DPA!D51 -> - | E34: =DPA!E51 -> Materai Spesifikasi: Materai 10.000 | K34: =DPA!S51 -> 150000 | M34: =K34 -> 150000
B36: =DPA!B53 -> 5.1.02.04 | C36: =DPA!C53 -> Belanja Perjalanan Dinas | K36: =DPA!S53 -> 31208000 | M36: =K36 -> 31208000
B37: =DPA!B54 -> 5.1.02.04.01 | C37: =DPA!C54 -> Belanja Perjalanan Dinas Dalam Negeri | D37: =DPA!D54 | E37: =DPA!E54 | K37: =DPA!S54 -> 31208000 | M37: =K37 -> 31208000
B38: =DPA!B55 -> 5.1.02.04.01.0001 | C38: =DPA!C55 -> Belanja Perjalanan Dinas Biasa | D38: =DPA!D55 | E38: =DPA!E55 | K38: =DPA!S55 -> 31208000 | M38: =K38 -> 31208000
D39: =DPA!D56 -> - | E39: =DPA!E56 -> Penginapan Dalam Negeri di- D.K.I. JAKARTA Spesifikasi: PEJABAT ESELON III / GOLONGAN IV | K39: =DPA!S56 -> 7936000 | M39: =K39 -> 7936000
D40: =DPA!D57 -> - | E40: =DPA!E57 -> Taxi dari/ke Bandara - Perjalanan Dinas Dalam Negeri Spesifikasi: BALI | K40: =DPA!S57 -> 1816000 | M40: =K40 -> 1816000
D41: =DPA!D58 -> - | E41: =DPA!E58 -> Taxi dari/ke Bandara - Perjalanan Dinas Dalam Negeri Spesifikasi: D.K.I. JAKARTA | K41: =DPA!S58 -> 2048000 | M41: =K41 -> 2048000
D42: =DPA!D59 -> - | E42: =DPA!E59 -> Satuan Biaya Tiket Dalam Negeri Spesifikasi : Denpasar - Jakarta | K42: =DPA!S59 -> 13048000 | M42: =K42 -> 13048000
D43: =DPA!D60 -> - | E43: =DPA!E60 -> Uang Harian Perjalanan Dinas Luar Kota/Luar Daerah Spesifikasi: D.K.I. JAKARTA | K43: =DPA!S60 -> 6360000 | M43: =K43 -> 6360000
B45: =DPA!B62 -> 5.2 | C45: =DPA!C62 -> Belanja Modal | K45: =DPA!S62 -> 61372400 | M45: =K45 -> 61372400
B46: =DPA!B63 -> 5.2.02 | C46: =DPA!C63 -> Belanja Modal Perapatan dan Mesin | K46: =DPA!S63 -> 61372400 | M46: =K46 -> 61372400
B47: =DPA!B64 -> 5.2.02.05 | C47: =DPA!C64 -> Belanja Modal Alat Kantor dan Rumah Tangga | K47: =DPA!S64 -> 61372400 | M47: =K47 -> 61372400
B48: =DPA!B65 -> 5.2.02.05.001 | C48: =DPA!C65 -> Belanja Modal Alat Kantor | K48: =DPA!S65 -> 34347600 | M48: =K48 -> 34347600
B49: =DPA!B66 -> 5.2.02.05.001.00005 | C49: =DPA!C66 -> Belanja Modal Alat Kantor Lainnya | K49: =DPA!S66 -> 34347600 | M49: =K49 -> 34347600
...

Sheet Peb
B1: LAPORAN REALISASI FISIK DAN KEUANGAN
B2: APBD PROVINSI BALI TAHUN 2026
B4: SKPD | D4: : | M4: PROGRAM
B5: SUB UNIT KERJA | D5: : | M5: KEGIATAN
B6: SUB BAGIAN | D6: : | M6: PPTK
B7: STATUS | D7: :
B9: KODE REKENING | C9: URAIAN BELANJA | F9: RENCANA KEGIATAN | L9: PELAKSANAAN KEGIATAN | T9: SALDO
F10: VOL | G10: SAT | H10: LOKASI | I10: JML PAKET | K10: ANGGARAN | L10: KONTRAK SWAKELOLA | M10: SISA ANGGARAN | N10: PROGRES
N11: FISIK | Q11: KEUANGAN
N12: RENC | O12: REAL | P12: DEV | Q12: RENC | R12: REAL Rp. | S12: %
B13: a | C13: b | F13: c | G13: d | H13: e | I13: f | K13: g | L13: h | M13: i | N13: j | O13: k | P13: l | Q13: m | R13: n | S13: o | T13: p
B14: =DPA!B31 -> 5 | C14: =DPA!C31 -> BELANJA DAERAH | K14: =DPA!S31 -> 94371800 | M14: =K14 -> 94371800
B15: =DPA!B32 -> 5.1 | C15: =DPA!C32 -> BELANJA OPERASI | K15: =DPA!S32 -> 32999400 | M15: =K15 -> 32999400
B17: =DPA!B34 -> 5.2.2. | C17: =DPA!C34 -> Belanja Barang dan Jasa | K17: =DPA!S34 -> 32999400 | M17: =K17 -> 32999400
B19: =DPA!B36 -> 5.2.2.01 | C19: =DPA!C36 -> Belanja Bahan Pakai Habis | K19: =DPA!S36 -> 1791400 | M19: =K19 -> 1791400
B21: =DPA!B38 -> 5.1.02.01.01.0024 | C21: =DPA!C38 -> Belanja Alat/Bahan untuk Kegiatan Kantor-Alat Tulis Kantor | K21: =DPA!S38 -> 656000 | M21: =K21 -> 656000
D22: =DPA!D39 -> - | E22: =DPA!E39 -> Alat Tulis Kantor Spesifikasi : Stof Map Folio | K22: =DPA!S39 -> 330000 | M22: =K22 -> 330000
D23: =DPA!D40 -> - | E23: =DPA!E40 -> Alat Tulis Kantor Spesifikasi : Trigonal Clip No. 5 Atom | K23: =DPA!S40 -> 66000 | M23: =K23 -> 66000
D24: =DPA!D41 -> - | E24: =DPA!E41 -> Alat Tulis Kantor Spesifikasi : Box File Jumbo Bantex | K24: =DPA!S41 -> 260000 | M24: =K24 -> 260000
K25: =DPA!S42 | M25: =K25
B26: =DPA!B43 -> 5.1.02.01.01.0025 | C26: =DPA!C43 -> Belanja Alat/Bahan untuk Kegiatan Kantor- Kertas dan Cover | K26: =DPA!S43 -> 441400 | M26: =K26 -> 441400
D27: =DPA!D44 -> - | E27: =DPA!E44 -> Kertas dan Cover Spesifikasi : Kertas HVS A4 70 gr | K27: =DPA!S44 -> 164800 | M27: =K27 -> 164800
D28: =DPA!D45 -> - | E28: =DPA!E45 -> Kertas dan Cover Spesifikasi : Kertas HVS F4 70 gr | K28: =DPA!S45 -> 276600 | M28: =K28 -> 276600
B30: =DPA!B47 -> 5.1.02.01.01.0026 | C30: =DPA!C47 -> Belanja Alat/Bahan untuk Kegiatan Kantor- Bahan Cetak | K30: =DPA!S47 -> 544000 | M30: =K30 -> 544000
D31: =DPA!D48 -> - | E31: =DPA!E48 -> Foto Copy Spesifikasi : Foto copy Hitam Putih-HVS A4/F4 | K31: =DPA!S48 -> 544000 | M31: =K31 -> 544000
B33: =DPA!B50 -> 5.1.02.01.01.0027 | C33: =DPA!C50 -> Belanja Alat/Bahan untuk Kegiatan Kantor-Benda Pos | K33: =DPA!S50 -> 150000 | M33: =K33 -> 150000
D34: =DPA!D51 -> - | E34: =DPA!E51 -> Materai Spesifikasi: Materai 10.000 | K34: =DPA!S51 -> 150000 | M34: =K34 -> 150000
B36: =DPA!B53 -> 5.1.02.04 | C36: =DPA!C53 -> Belanja Perjalanan Dinas | K36: =DPA!S53 -> 31208000 | M36: =K36 -> 31208000
B37: =DPA!B54 -> 5.1.02.04.01 | C37: =DPA!C54 -> Belanja Perjalanan Dinas Dalam Negeri | D37: =DPA!D54 | E37: =DPA!E54 | K37: =DPA!S54 -> 31208000 | M37: =K37 -> 31208000
B38: =DPA!B55 -> 5.1.02.04.01.0001 | C38: =DPA!C55 -> Belanja Perjalanan Dinas Biasa | D38: =DPA!D55 | E38: =DPA!E55 | K38: =DPA!S55 -> 31208000 | M38: =K38 -> 31208000
D39: =DPA!D56 -> - | E39: =DPA!E56 -> Penginapan Dalam Negeri di- D.K.I. JAKARTA Spesifikasi: PEJABAT ESELON III / GOLONGAN IV | K39: =DPA!S56 -> 7936000 | M39: =K39 -> 7936000
D40: =DPA!D57 -> - | E40: =DPA!E57 -> Taxi dari/ke Bandara - Perjalanan Dinas Dalam Negeri Spesifikasi: BALI | K40: =DPA!S57 -> 1816000 | M40: =K40 -> 1816000
D41: =DPA!D58 -> - | E41: =DPA!E58 -> Taxi dari/ke Bandara - Perjalanan Dinas Dalam Negeri Spesifikasi: D.K.I. JAKARTA | K41: =DPA!S58 -> 2048000 | M41: =K41 -> 2048000
D42: =DPA!D59 -> - | E42: =DPA!E59 -> Satuan Biaya Tiket Dalam Negeri Spesifikasi : Denpasar - Jakarta | K42: =DPA!S59 -> 13048000 | M42: =K42 -> 13048000
D43: =DPA!D60 -> - | E43: =DPA!E60 -> Uang Harian Perjalanan Dinas Luar Kota/Luar Daerah Spesifikasi: D.K.I. JAKARTA | K43: =DPA!S60 -> 6360000 | M43: =K43 -> 6360000
B45: =DPA!B62 -> 5.2 | C45: =DPA!C62 -> Belanja Modal | K45: =DPA!S62 -> 61372400 | M45: =K45 -> 61372400
B46: =DPA!B63 -> 5.2.02 | C46: =DPA!C63 -> Belanja Modal Perapatan dan Mesin | K46: =DPA!S63 -> 61372400 | M46: =K46 -> 61372400
B47: =DPA!B64 -> 5.2.02.05 | C47: =DPA!C64 -> Belanja Modal Alat Kantor dan Rumah Tangga | K47: =DPA!S64 -> 61372400 | M47: =K47 -> 61372400
B48: =DPA!B65 -> 5.2.02.05.001 | C48: =DPA!C65 -> Belanja Modal Alat Kantor | K48: =DPA!S65 -> 34347600 | M48: =K48 -> 34347600
B49: =DPA!B66 -> 5.2.02.05.001.00005 | C49: =DPA!C66 -> Belanja Modal Alat Kantor Lainnya | K49: =DPA!S66 -> 34347600 | M49: =K49 -> 34347600
...

Sheet Mar
B1: LAPORAN REALISASI FISIK DAN KEUANGAN
B2: APBD PROVINSI BALI TAHUN 2026
B4: SKPD | D4: : | M4: PROGRAM
B5: SUB UNIT KERJA | D5: : | M5: KEGIATAN
B6: SUB BAGIAN | D6: : | M6: PPTK
B7: STATUS | D7: :
B9: KODE REKENING | C9: URAIAN BELANJA | F9: RENCANA KEGIATAN | L9: PELAKSANAAN KEGIATAN | T9: SALDO
F10: VOL | G10: SAT | H10: LOKASI | I10: JML PAKET | K10: ANGGARAN | L10: KONTRAK SWAKELOLA | M10: SISA ANGGARAN | N10: PROGRES
N11: FISIK | Q11: KEUANGAN
N12: RENC | O12: REAL | P12: DEV | Q12: RENC | R12: REAL Rp. | S12: %
B13: a | C13: b | F13: c | G13: d | H13: e | I13: f | K13: g | L13: h | M13: i | N13: j | O13: k | P13: l | Q13: m | R13: n | S13: o | T13: p
B14: =DPA!B31 -> 5 | C14: =DPA!C31 -> BELANJA DAERAH | K14: =DPA!S31 -> 94371800 | M14: =K14 -> 94371800
B15: =DPA!B32 -> 5.1 | C15: =DPA!C32 -> BELANJA OPERASI | K15: =DPA!S32 -> 32999400 | M15: =K15 -> 32999400
B17: =DPA!B34 -> 5.2.2. | C17: =DPA!C34 -> Belanja Barang dan Jasa | K17: =DPA!S34 -> 32999400 | M17: =K17 -> 32999400
B19: =DPA!B36 -> 5.2.2.01 | C19: =DPA!C36 -> Belanja Bahan Pakai Habis | K19: =DPA!S36 -> 1791400 | M19: =K19 -> 1791400
B21: =DPA!B38 -> 5.1.02.01.01.0024 | C21: =DPA!C38 -> Belanja Alat/Bahan untuk Kegiatan Kantor-Alat Tulis Kantor | K21: =DPA!S38 -> 656000 | M21: =K21 -> 656000
D22: =DPA!D39 -> - | E22: =DPA!E39 -> Alat Tulis Kantor Spesifikasi : Stof Map Folio | K22: =DPA!S39 -> 330000 | M22: =K22 -> 330000
D23: =DPA!D40 -> - | E23: =DPA!E40 -> Alat Tulis Kantor Spesifikasi : Trigonal Clip No. 5 Atom | K23: =DPA!S40 -> 66000 | M23: =K23 -> 66000
D24: =DPA!D41 -> - | E24: =DPA!E41 -> Alat Tulis Kantor Spesifikasi : Box File Jumbo Bantex | K24: =DPA!S41 -> 260000 | M24: =K24 -> 260000
K25: =DPA!S42 | M25: =K25
B26: =DPA!B43 -> 5.1.02.01.01.0025 | C26: =DPA!C43 -> Belanja Alat/Bahan untuk Kegiatan Kantor- Kertas dan Cover | K26: =DPA!S43 -> 441400 | M26: =K26 -> 441400
D27: =DPA!D44 -> - | E27: =DPA!E44 -> Kertas dan Cover Spesifikasi : Kertas HVS A4 70 gr | K27: =DPA!S44 -> 164800 | M27: =K27 -> 164800
D28: =DPA!D45 -> - | E28: =DPA!E45 -> Kertas dan Cover Spesifikasi : Kertas HVS F4 70 gr | K28: =DPA!S45 -> 276600 | M28: =K28 -> 276600
B30: =DPA!B47 -> 5.1.02.01.01.0026 | C30: =DPA!C47 -> Belanja Alat/Bahan untuk Kegiatan Kantor- Bahan Cetak | K30: =DPA!S47 -> 544000 | M30: =K30 -> 544000
D31: =DPA!D48 -> - | E31: =DPA!E48 -> Foto Copy Spesifikasi : Foto copy Hitam Putih-HVS A4/F4 | K31: =DPA!S48 -> 544000 | M31: =K31 -> 544000
B33: =DPA!B50 -> 5.1.02.01.01.0027 | C33: =DPA!C50 -> Belanja Alat/Bahan untuk Kegiatan Kantor-Benda Pos | K33: =DPA!S50 -> 150000 | M33: =K33 -> 150000
D34: =DPA!D51 -> - | E34: =DPA!E51 -> Materai Spesifikasi: Materai 10.000 | K34: =DPA!S51 -> 150000 | M34: =K34 -> 150000
B36: =DPA!B53 -> 5.1.02.04 | C36: =DPA!C53 -> Belanja Perjalanan Dinas | K36: =DPA!S53 -> 31208000 | M36: =K36 -> 31208000
B37: =DPA!B54 -> 5.1.02.04.01 | C37: =DPA!C54 -> Belanja Perjalanan Dinas Dalam Negeri | D37: =DPA!D54 | E37: =DPA!E54 | K37: =DPA!S54 -> 31208000 | M37: =K37 -> 31208000
B38: =DPA!B55 -> 5.1.02.04.01.0001 | C38: =DPA!C55 -> Belanja Perjalanan Dinas Biasa | D38: =DPA!D55 | E38: =DPA!E55 | K38: =DPA!S55 -> 31208000 | M38: =K38 -> 31208000
D39: =DPA!D56 -> - | E39: =DPA!E56 -> Penginapan Dalam Negeri di- D.K.I. JAKARTA Spesifikasi: PEJABAT ESELON III / GOLONGAN IV | K39: =DPA!S56 -> 7936000 | M39: =K39 -> 7936000
D40: =DPA!D57 -> - | E40: =DPA!E57 -> Taxi dari/ke Bandara - Perjalanan Dinas Dalam Negeri Spesifikasi: BALI | K40: =DPA!S57 -> 1816000 | M40: =K40 -> 1816000
D41: =DPA!D58 -> - | E41: =DPA!E58 -> Taxi dari/ke Bandara - Perjalanan Dinas Dalam Negeri Spesifikasi: D.K.I. JAKARTA | K41: =DPA!S58 -> 2048000 | M41: =K41 -> 2048000
D42: =DPA!D59 -> - | E42: =DPA!E59 -> Satuan Biaya Tiket Dalam Negeri Spesifikasi : Denpasar - Jakarta | K42: =DPA!S59 -> 13048000 | M42: =K42 -> 13048000
D43: =DPA!D60 -> - | E43: =DPA!E60 -> Uang Harian Perjalanan Dinas Luar Kota/Luar Daerah Spesifikasi: D.K.I. JAKARTA | K43: =DPA!S60 -> 6360000 | M43: =K43 -> 6360000
B45: =DPA!B62 -> 5.2 | C45: =DPA!C62 -> Belanja Modal | K45: =DPA!S62 -> 61372400 | M45: =K45 -> 61372400
B46: =DPA!B63 -> 5.2.02 | C46: =DPA!C63 -> Belanja Modal Perapatan dan Mesin | K46: =DPA!S63 -> 61372400 | M46: =K46 -> 61372400
B47: =DPA!B64 -> 5.2.02.05 | C47: =DPA!C64 -> Belanja Modal Alat Kantor dan Rumah Tangga | K47: =DPA!S64 -> 61372400 | M47: =K47 -> 61372400
B48: =DPA!B65 -> 5.2.02.05.001 | C48: =DPA!C65 -> Belanja Modal Alat Kantor | K48: =DPA!S65 -> 34347600 | M48: =K48 -> 34347600
B49: =DPA!B66 -> 5.2.02.05.001.00005 | C49: =DPA!C66 -> Belanja Modal Alat Kantor Lainnya | K49: =DPA!S66 -> 34347600 | M49: =K49 -> 34347600
...

Sheet Apr
B1: LAPORAN REALISASI FISIK DAN KEUANGAN
B2: APBD PROVINSI BALI TAHUN 2026
B4: SKPD | D4: : | M4: PROGRAM
B5: SUB UNIT KERJA | D5: : | M5: KEGIATAN
B6: SUB BAGIAN | D6: : | M6: PPTK
B7: STATUS | D7: :
B9: KODE REKENING | C9: URAIAN BELANJA | F9: RENCANA KEGIATAN | L9: PELAKSANAAN KEGIATAN | T9: SALDO
F10: VOL | G10: SAT | H10: LOKASI | I10: JML PAKET | K10: ANGGARAN | L10: KONTRAK SWAKELOLA | M10: SISA ANGGARAN | N10: PROGRES
N11: FISIK | Q11: KEUANGAN
N12: RENC | O12: REAL | P12: DEV | Q12: RENC | R12: REAL Rp. | S12: %
B13: a | C13: b | F13: c | G13: d | H13: e | I13: f | K13: g | L13: h | M13: i | N13: j | O13: k | P13: l | Q13: m | R13: n | S13: o | T13: p
B14: =DPA!B31 -> 5 | C14: =DPA!C31 -> BELANJA DAERAH | K14: =DPA!S31 -> 94371800 | M14: =K14 -> 94371800
B15: =DPA!B32 -> 5.1 | C15: =DPA!C32 -> BELANJA OPERASI | K15: =DPA!S32 -> 32999400 | M15: =K15 -> 32999400
B17: =DPA!B34 -> 5.2.2. | C17: =DPA!C34 -> Belanja Barang dan Jasa | K17: =DPA!S34 -> 32999400 | M17: =K17 -> 32999400
B19: =DPA!B36 -> 5.2.2.01 | C19: =DPA!C36 -> Belanja Bahan Pakai Habis | K19: =DPA!S36 -> 1791400 | M19: =K19 -> 1791400
B21: =DPA!B38 -> 5.1.02.01.01.0024 | C21: =DPA!C38 -> Belanja Alat/Bahan untuk Kegiatan Kantor-Alat Tulis Kantor | K21: =DPA!S38 -> 656000 | M21: =K21 -> 656000
D22: =DPA!D39 -> - | E22: =DPA!E39 -> Alat Tulis Kantor Spesifikasi : Stof Map Folio | K22: =DPA!S39 -> 330000 | M22: =K22 -> 330000
D23: =DPA!D40 -> - | E23: =DPA!E40 -> Alat Tulis Kantor Spesifikasi : Trigonal Clip No. 5 Atom | K23: =DPA!S40 -> 66000 | M23: =K23 -> 66000
D24: =DPA!D41 -> - | E24: =DPA!E41 -> Alat Tulis Kantor Spesifikasi : Box File Jumbo Bantex | K24: =DPA!S41 -> 260000 | M24: =K24 -> 260000
K25: =DPA!S42 | M25: =K25
B26: =DPA!B43 -> 5.1.02.01.01.0025 | C26: =DPA!C43 -> Belanja Alat/Bahan untuk Kegiatan Kantor- Kertas dan Cover | K26: =DPA!S43 -> 441400 | M26: =K26 -> 441400
D27: =DPA!D44 -> - | E27: =DPA!E44 -> Kertas dan Cover Spesifikasi : Kertas HVS A4 70 gr | K27: =DPA!S44 -> 164800 | M27: =K27 -> 164800
D28: =DPA!D45 -> - | E28: =DPA!E45 -> Kertas dan Cover Spesifikasi : Kertas HVS F4 70 gr | K28: =DPA!S45 -> 276600 | M28: =K28 -> 276600
B30: =DPA!B47 -> 5.1.02.01.01.0026 | C30: =DPA!C47 -> Belanja Alat/Bahan untuk Kegiatan Kantor- Bahan Cetak | K30: =DPA!S47 -> 544000 | M30: =K30 -> 544000
D31: =DPA!D48 -> - | E31: =DPA!E48 -> Foto Copy Spesifikasi : Foto copy Hitam Putih-HVS A4/F4 | K31: =DPA!S48 -> 544000 | M31: =K31 -> 544000
B33: =DPA!B50 -> 5.1.02.01.01.0027 | C33: =DPA!C50 -> Belanja Alat/Bahan untuk Kegiatan Kantor-Benda Pos | K33: =DPA!S50 -> 150000 | M33: =K33 -> 150000
D34: =DPA!D51 -> - | E34: =DPA!E51 -> Materai Spesifikasi: Materai 10.000 | K34: =DPA!S51 -> 150000 | M34: =K34 -> 150000
B36: =DPA!B53 -> 5.1.02.04 | C36: =DPA!C53 -> Belanja Perjalanan Dinas | K36: =DPA!S53 -> 31208000 | M36: =K36 -> 31208000
B37: =DPA!B54 -> 5.1.02.04.01 | C37: =DPA!C54 -> Belanja Perjalanan Dinas Dalam Negeri | D37: =DPA!D54 | E37: =DPA!E54 | K37: =DPA!S54 -> 31208000 | M37: =K37 -> 31208000
B38: =DPA!B55 -> 5.1.02.04.01.0001 | C38: =DPA!C55 -> Belanja Perjalanan Dinas Biasa | D38: =DPA!D55 | E38: =DPA!E55 | K38: =DPA!S55 -> 31208000 | M38: =K38 -> 31208000
D39: =DPA!D56 -> - | E39: =DPA!E56 -> Penginapan Dalam Negeri di- D.K.I. JAKARTA Spesifikasi: PEJABAT ESELON III / GOLONGAN IV | K39: =DPA!S56 -> 7936000 | M39: =K39 -> 7936000
D40: =DPA!D57 -> - | E40: =DPA!E57 -> Taxi dari/ke Bandara - Perjalanan Dinas Dalam Negeri Spesifikasi: BALI | K40: =DPA!S57 -> 1816000 | M40: =K40 -> 1816000
D41: =DPA!D58 -> - | E41: =DPA!E58 -> Taxi dari/ke Bandara - Perjalanan Dinas Dalam Negeri Spesifikasi: D.K.I. JAKARTA | K41: =DPA!S58 -> 2048000 | M41: =K41 -> 2048000
D42: =DPA!D59 -> - | E42: =DPA!E59 -> Satuan Biaya Tiket Dalam Negeri Spesifikasi : Denpasar - Jakarta | K42: =DPA!S59 -> 13048000 | M42: =K42 -> 13048000
D43: =DPA!D60 -> - | E43: =DPA!E60 -> Uang Harian Perjalanan Dinas Luar Kota/Luar Daerah Spesifikasi: D.K.I. JAKARTA | K43: =DPA!S60 -> 6360000 | M43: =K43 -> 6360000
B45: =DPA!B62 -> 5.2 | C45: =DPA!C62 -> Belanja Modal | K45: =DPA!S62 -> 61372400 | M45: =K45 -> 61372400
B46: =DPA!B63 -> 5.2.02 | C46: =DPA!C63 -> Belanja Modal Perapatan dan Mesin | K46: =DPA!S63 -> 61372400 | M46: =K46 -> 61372400
B47: =DPA!B64 -> 5.2.02.05 | C47: =DPA!C64 -> Belanja Modal Alat Kantor dan Rumah Tangga | K47: =DPA!S64 -> 61372400 | M47: =K47 -> 61372400
B48: =DPA!B65 -> 5.2.02.05.001 | C48: =DPA!C65 -> Belanja Modal Alat Kantor | K48: =DPA!S65 -> 34347600 | M48: =K48 -> 34347600
B49: =DPA!B66 -> 5.2.02.05.001.00005 | C49: =DPA!C66 -> Belanja Modal Alat Kantor Lainnya | K49: =DPA!S66 -> 34347600 | M49: =K49 -> 34347600
...

Sheet Mei
B1: LAPORAN REALISASI FISIK DAN KEUANGAN
B2: APBD PROVINSI BALI TAHUN 2026
B4: SKPD | D4: : | M4: PROGRAM
B5: SUB UNIT KERJA | D5: : | M5: KEGIATAN
B6: SUB BAGIAN | D6: : | M6: PPTK
B7: STATUS | D7: :
B9: KODE REKENING | C9: URAIAN BELANJA | F9: RENCANA KEGIATAN | L9: PELAKSANAAN KEGIATAN | T9: SALDO
F10: VOL | G10: SAT | H10: LOKASI | I10: JML PAKET | K10: ANGGARAN | L10: KONTRAK SWAKELOLA | M10: SISA ANGGARAN | N10: PROGRES
N11: FISIK | Q11: KEUANGAN
N12: RENC | O12: REAL | P12: DEV | Q12: RENC | R12: REAL Rp. | S12: %
B13: a | C13: b | F13: c | G13: d | H13: e | I13: f | K13: g | L13: h | M13: i | N13: j | O13: k | P13: l | Q13: m | R13: n | S13: o | T13: p
B14: =DPA!B31 -> 5 | C14: =DPA!C31 -> BELANJA DAERAH | K14: =DPA!S31 -> 94371800 | M14: =K14 -> 94371800
B15: =DPA!B32 -> 5.1 | C15: =DPA!C32 -> BELANJA OPERASI | K15: =DPA!S32 -> 32999400 | M15: =K15 -> 32999400
B17: =DPA!B34 -> 5.2.2. | C17: =DPA!C34 -> Belanja Barang dan Jasa | K17: =DPA!S34 -> 32999400 | M17: =K17 -> 32999400
B19: =DPA!B36 -> 5.2.2.01 | C19: =DPA!C36 -> Belanja Bahan Pakai Habis | K19: =DPA!S36 -> 1791400 | M19: =K19 -> 1791400
B21: =DPA!B38 -> 5.1.02.01.01.0024 | C21: =DPA!C38 -> Belanja Alat/Bahan untuk Kegiatan Kantor-Alat Tulis Kantor | K21: =DPA!S38 -> 656000 | M21: =K21 -> 656000
D22: =DPA!D39 -> - | E22: =DPA!E39 -> Alat Tulis Kantor Spesifikasi : Stof Map Folio | K22: =DPA!S39 -> 330000 | M22: =K22 -> 330000
D23: =DPA!D40 -> - | E23: =DPA!E40 -> Alat Tulis Kantor Spesifikasi : Trigonal Clip No. 5 Atom | K23: =DPA!S40 -> 66000 | M23: =K23 -> 66000
D24: =DPA!D41 -> - | E24: =DPA!E41 -> Alat Tulis Kantor Spesifikasi : Box File Jumbo Bantex | K24: =DPA!S41 -> 260000 | M24: =K24 -> 260000
K25: =DPA!S42 | M25: =K25
B26: =DPA!B43 -> 5.1.02.01.01.0025 | C26: =DPA!C43 -> Belanja Alat/Bahan untuk Kegiatan Kantor- Kertas dan Cover | K26: =DPA!S43 -> 441400 | M26: =K26 -> 441400
D27: =DPA!D44 -> - | E27: =DPA!E44 -> Kertas dan Cover Spesifikasi : Kertas HVS A4 70 gr | K27: =DPA!S44 -> 164800 | M27: =K27 -> 164800
D28: =DPA!D45 -> - | E28: =DPA!E45 -> Kertas dan Cover Spesifikasi : Kertas HVS F4 70 gr | K28: =DPA!S45 -> 276600 | M28: =K28 -> 276600
B30: =DPA!B47 -> 5.1.02.01.01.0026 | C30: =DPA!C47 -> Belanja Alat/Bahan untuk Kegiatan Kantor- Bahan Cetak | K30: =DPA!S47 -> 544000 | M30: =K30 -> 544000
D31: =DPA!D48 -> - | E31: =DPA!E48 -> Foto Copy Spesifikasi : Foto copy Hitam Putih-HVS A4/F4 | K31: =DPA!S48 -> 544000 | M31: =K31 -> 544000
B33: =DPA!B50 -> 5.1.02.01.01.0027 | C33: =DPA!C50 -> Belanja Alat/Bahan untuk Kegiatan Kantor-Benda Pos | K33: =DPA!S50 -> 150000 | M33: =K33 -> 150000
D34: =DPA!D51 -> - | E34: =DPA!E51 -> Materai Spesifikasi: Materai 10.000 | K34: =DPA!S51 -> 150000 | M34: =K34 -> 150000
B36: =DPA!B53 -> 5.1.02.04 | C36: =DPA!C53 -> Belanja Perjalanan Dinas | K36: =DPA!S53 -> 31208000 | M36: =K36 -> 31208000
B37: =DPA!B54 -> 5.1.02.04.01 | C37: =DPA!C54 -> Belanja Perjalanan Dinas Dalam Negeri | D37: =DPA!D54 | E37: =DPA!E54 | K37: =DPA!S54 -> 31208000 | M37: =K37 -> 31208000
B38: =DPA!B55 -> 5.1.02.04.01.0001 | C38: =DPA!C55 -> Belanja Perjalanan Dinas Biasa | D38: =DPA!D55 | E38: =DPA!E55 | K38: =DPA!S55 -> 31208000 | M38: =K38 -> 31208000
D39: =DPA!D56 -> - | E39: =DPA!E56 -> Penginapan Dalam Negeri di- D.K.I. JAKARTA Spesifikasi: PEJABAT ESELON III / GOLONGAN IV | K39: =DPA!S56 -> 7936000 | M39: =K39 -> 7936000
D40: =DPA!D57 -> - | E40: =DPA!E57 -> Taxi dari/ke Bandara - Perjalanan Dinas Dalam Negeri Spesifikasi: BALI | K40: =DPA!S57 -> 1816000 | M40: =K40 -> 1816000
D41: =DPA!D58 -> - | E41: =DPA!E58 -> Taxi dari/ke Bandara - Perjalanan Dinas Dalam Negeri Spesifikasi: D.K.I. JAKARTA | K41: =DPA!S58 -> 2048000 | M41: =K41 -> 2048000
D42: =DPA!D59 -> - | E42: =DPA!E59 -> Satuan Biaya Tiket Dalam Negeri Spesifikasi : Denpasar - Jakarta | K42: =DPA!S59 -> 13048000 | M42: =K42 -> 13048000
D43: =DPA!D60 -> - | E43: =DPA!E60 -> Uang Harian Perjalanan Dinas Luar Kota/Luar Daerah Spesifikasi: D.K.I. JAKARTA | K43: =DPA!S60 -> 6360000 | M43: =K43 -> 6360000
B45: =DPA!B62 -> 5.2 | C45: =DPA!C62 -> Belanja Modal | K45: =DPA!S62 -> 61372400 | M45: =K45 -> 61372400
B46: =DPA!B63 -> 5.2.02 | C46: =DPA!C63 -> Belanja Modal Perapatan dan Mesin | K46: =DPA!S63 -> 61372400 | M46: =K46 -> 61372400
B47: =DPA!B64 -> 5.2.02.05 | C47: =DPA!C64 -> Belanja Modal Alat Kantor dan Rumah Tangga | K47: =DPA!S64 -> 61372400 | M47: =K47 -> 61372400
B48: =DPA!B65 -> 5.2.02.05.001 | C48: =DPA!C65 -> Belanja Modal Alat Kantor | K48: =DPA!S65 -> 34347600 | M48: =K48 -> 34347600
B49: =DPA!B66 -> 5.2.02.05.001.00005 | C49: =DPA!C66 -> Belanja Modal Alat Kantor Lainnya | K49: =DPA!S66 -> 34347600 | M49: =K49 -> 34347600
...

Sheet Juni
B1: LAPORAN REALISASI FISIK DAN KEUANGAN
B2: APBD PROVINSI BALI TAHUN 2026
B4: SKPD | D4: : | M4: PROGRAM
B5: SUB UNIT KERJA | D5: : | M5: KEGIATAN
B6: SUB BAGIAN | D6: : | M6: PPTK
B7: STATUS | D7: :
B9: KODE REKENING | C9: URAIAN BELANJA | F9: RENCANA KEGIATAN | L9: PELAKSANAAN KEGIATAN | T9: SALDO
F10: VOL | G10: SAT | H10: LOKASI | I10: JML PAKET | K10: ANGGARAN | L10: KONTRAK SWAKELOLA | M10: SISA ANGGARAN | N10: PROGRES
N11: FISIK | Q11: KEUANGAN
N12: RENC | O12: REAL | P12: DEV | Q12: RENC | R12: REAL Rp. | S12: %
B13: a | C13: b | F13: c | G13: d | H13: e | I13: f | K13: g | L13: h | M13: i | N13: j | O13: k | P13: l | Q13: m | R13: n | S13: o | T13: p
B14: =DPA!B31 -> 5 | C14: =DPA!C31 -> BELANJA DAERAH | K14: =DPA!S31 -> 94371800 | M14: =K14 -> 94371800
B15: =DPA!B32 -> 5.1 | C15: =DPA!C32 -> BELANJA OPERASI | K15: =DPA!S32 -> 32999400 | M15: =K15 -> 32999400
B17: =DPA!B34 -> 5.2.2. | C17: =DPA!C34 -> Belanja Barang dan Jasa | K17: =DPA!S34 -> 32999400 | M17: =K17 -> 32999400
B19: =DPA!B36 -> 5.2.2.01 | C19: =DPA!C36 -> Belanja Bahan Pakai Habis | K19: =DPA!S36 -> 1791400 | M19: =K19 -> 1791400
B21: =DPA!B38 -> 5.1.02.01.01.0024 | C21: =DPA!C38 -> Belanja Alat/Bahan untuk Kegiatan Kantor-Alat Tulis Kantor | K21: =DPA!S38 -> 656000 | M21: =K21 -> 656000
D22: =DPA!D39 -> - | E22: =DPA!E39 -> Alat Tulis Kantor Spesifikasi : Stof Map Folio | K22: =DPA!S39 -> 330000 | M22: =K22 -> 330000
D23: =DPA!D40 -> - | E23: =DPA!E40 -> Alat Tulis Kantor Spesifikasi : Trigonal Clip No. 5 Atom | K23: =DPA!S40 -> 66000 | M23: =K23 -> 66000
D24: =DPA!D41 -> - | E24: =DPA!E41 -> Alat Tulis Kantor Spesifikasi : Box File Jumbo Bantex | K24: =DPA!S41 -> 260000 | M24: =K24 -> 260000
K25: =DPA!S42 | M25: =K25
B26: =DPA!B43 -> 5.1.02.01.01.0025 | C26: =DPA!C43 -> Belanja Alat/Bahan untuk Kegiatan Kantor- Kertas dan Cover | K26: =DPA!S43 -> 441400 | M26: =K26 -> 441400
D27: =DPA!D44 -> - | E27: =DPA!E44 -> Kertas dan Cover Spesifikasi : Kertas HVS A4 70 gr | K27: =DPA!S44 -> 164800 | M27: =K27 -> 164800
D28: =DPA!D45 -> - | E28: =DPA!E45 -> Kertas dan Cover Spesifikasi : Kertas HVS F4 70 gr | K28: =DPA!S45 -> 276600 | M28: =K28 -> 276600
B30: =DPA!B47 -> 5.1.02.01.01.0026 | C30: =DPA!C47 -> Belanja Alat/Bahan untuk Kegiatan Kantor- Bahan Cetak | K30: =DPA!S47 -> 544000 | M30: =K30 -> 544000
D31: =DPA!D48 -> - | E31: =DPA!E48 -> Foto Copy Spesifikasi : Foto copy Hitam Putih-HVS A4/F4 | K31: =DPA!S48 -> 544000 | M31: =K31 -> 544000
B33: =DPA!B50 -> 5.1.02.01.01.0027 | C33: =DPA!C50 -> Belanja Alat/Bahan untuk Kegiatan Kantor-Benda Pos | K33: =DPA!S50 -> 150000 | M33: =K33 -> 150000
D34: =DPA!D51 -> - | E34: =DPA!E51 -> Materai Spesifikasi: Materai 10.000 | K34: =DPA!S51 -> 150000 | M34: =K34 -> 150000
B36: =DPA!B53 -> 5.1.02.04 | C36: =DPA!C53 -> Belanja Perjalanan Dinas | K36: =DPA!S53 -> 31208000 | M36: =K36 -> 31208000
B37: =DPA!B54 -> 5.1.02.04.01 | C37: =DPA!C54 -> Belanja Perjalanan Dinas Dalam Negeri | D37: =DPA!D54 | E37: =DPA!E54 | K37: =DPA!S54 -> 31208000 | M37: =K37 -> 31208000
B38: =DPA!B55 -> 5.1.02.04.01.0001 | C38: =DPA!C55 -> Belanja Perjalanan Dinas Biasa | D38: =DPA!D55 | E38: =DPA!E55 | K38: =DPA!S55 -> 31208000 | M38: =K38 -> 31208000
D39: =DPA!D56 -> - | E39: =DPA!E56 -> Penginapan Dalam Negeri di- D.K.I. JAKARTA Spesifikasi: PEJABAT ESELON III / GOLONGAN IV | K39: =DPA!S56 -> 7936000 | M39: =K39 -> 7936000
D40: =DPA!D57 -> - | E40: =DPA!E57 -> Taxi dari/ke Bandara - Perjalanan Dinas Dalam Negeri Spesifikasi: BALI | K40: =DPA!S57 -> 1816000 | M40: =K40 -> 1816000
D41: =DPA!D58 -> - | E41: =DPA!E58 -> Taxi dari/ke Bandara - Perjalanan Dinas Dalam Negeri Spesifikasi: D.K.I. JAKARTA | K41: =DPA!S58 -> 2048000 | M41: =K41 -> 2048000
D42: =DPA!D59 -> - | E42: =DPA!E59 -> Satuan Biaya Tiket Dalam Negeri Spesifikasi : Denpasar - Jakarta | K42: =DPA!S59 -> 13048000 | M42: =K42 -> 13048000
D43: =DPA!D60 -> - | E43: =DPA!E60 -> Uang Harian Perjalanan Dinas Luar Kota/Luar Daerah Spesifikasi: D.K.I. JAKARTA | K43: =DPA!S60 -> 6360000 | M43: =K43 -> 6360000
B45: =DPA!B62 -> 5.2 | C45: =DPA!C62 -> Belanja Modal | K45: =DPA!S62 -> 61372400 | M45: =K45 -> 61372400
B46: =DPA!B63 -> 5.2.02 | C46: =DPA!C63 -> Belanja Modal Perapatan dan Mesin | K46: =DPA!S63 -> 61372400 | M46: =K46 -> 61372400
B47: =DPA!B64 -> 5.2.02.05 | C47: =DPA!C64 -> Belanja Modal Alat Kantor dan Rumah Tangga | K47: =DPA!S64 -> 61372400 | M47: =K47 -> 61372400
B48: =DPA!B65 -> 5.2.02.05.001 | C48: =DPA!C65 -> Belanja Modal Alat Kantor | K48: =DPA!S65 -> 34347600 | M48: =K48 -> 34347600
B49: =DPA!B66 -> 5.2.02.05.001.00005 | C49: =DPA!C66 -> Belanja Modal Alat Kantor Lainnya | K49: =DPA!S66 -> 34347600 | M49: =K49 -> 34347600
...

Sheet Juli
B1: LAPORAN REALISASI FISIK DAN KEUANGAN
B2: APBD PROVINSI BALI TAHUN 2026
B4: SKPD | D4: : | M4: PROGRAM
B5: SUB UNIT KERJA | D5: : | M5: KEGIATAN
B6: SUB BAGIAN | D6: : | M6: PPTK
B7: STATUS | D7: :
R8: Fn:C\Pramana\12PemelLGK.xls
B9: KODE REKENING | C9: URAIAN BELANJA | F9: RENCANA KEGIATAN | L9: PELAKSANAAN KEGIATAN | T9: SALDO
F10: VOL | G10: SAT | H10: LOKASI | I10: JML PAKET | K10: ANGGARAN | L10: KONTRAK SWAKELOLA | M10: SISA ANGGARAN | N10: PROGRES
N11: FISIK | Q11: KEUANGAN
N12: RENC | O12: REAL | P12: DEV | Q12: RENC | R12: REAL Rp. | S12: %
B13: a | C13: b | F13: c | G13: d | H13: e | I13: f | K13: g | L13: h | M13: i | N13: j | O13: k | P13: l | Q13: m | R13: n | S13: o | T13: p
B14: =DPA!B31 -> 5 | C14: =DPA!C31 -> BELANJA DAERAH | K14: =DPA!S31 -> 94371800 | M14: =K14 -> 94371800
B15: =DPA!B32 -> 5.1 | C15: =DPA!C32 -> BELANJA OPERASI | K15: =DPA!S32 -> 32999400 | M15: =K15 -> 32999400
B17: =DPA!B34 -> 5.2.2. | C17: =DPA!C34 -> Belanja Barang dan Jasa | K17: =DPA!S34 -> 32999400 | M17: =K17 -> 32999400
B19: =DPA!B36 -> 5.2.2.01 | C19: =DPA!C36 -> Belanja Bahan Pakai Habis | K19: =DPA!S36 -> 1791400 | M19: =K19 -> 1791400
B21: =DPA!B38 -> 5.1.02.01.01.0024 | C21: =DPA!C38 -> Belanja Alat/Bahan untuk Kegiatan Kantor-Alat Tulis Kantor | K21: =DPA!S38 -> 656000 | M21: =K21 -> 656000
D22: =DPA!D39 -> - | E22: =DPA!E39 -> Alat Tulis Kantor Spesifikasi : Stof Map Folio | K22: =DPA!S39 -> 330000 | M22: =K22 -> 330000
D23: =DPA!D40 -> - | E23: =DPA!E40 -> Alat Tulis Kantor Spesifikasi : Trigonal Clip No. 5 Atom | K23: =DPA!S40 -> 66000 | M23: =K23 -> 66000
D24: =DPA!D41 -> - | E24: =DPA!E41 -> Alat Tulis Kantor Spesifikasi : Box File Jumbo Bantex | K24: =DPA!S41 -> 260000 | M24: =K24 -> 260000
K25: =DPA!S42 | M25: =K25
B26: =DPA!B43 -> 5.1.02.01.01.0025 | C26: =DPA!C43 -> Belanja Alat/Bahan untuk Kegiatan Kantor- Kertas dan Cover | K26: =DPA!S43 -> 441400 | M26: =K26 -> 441400
D27: =DPA!D44 -> - | E27: =DPA!E44 -> Kertas dan Cover Spesifikasi : Kertas HVS A4 70 gr | K27: =DPA!S44 -> 164800 | M27: =K27 -> 164800
D28: =DPA!D45 -> - | E28: =DPA!E45 -> Kertas dan Cover Spesifikasi : Kertas HVS F4 70 gr | K28: =DPA!S45 -> 276600 | M28: =K28 -> 276600
B30: =DPA!B47 -> 5.1.02.01.01.0026 | C30: =DPA!C47 -> Belanja Alat/Bahan untuk Kegiatan Kantor- Bahan Cetak | K30: =DPA!S47 -> 544000 | M30: =K30 -> 544000
D31: =DPA!D48 -> - | E31: =DPA!E48 -> Foto Copy Spesifikasi : Foto copy Hitam Putih-HVS A4/F4 | K31: =DPA!S48 -> 544000 | M31: =K31 -> 544000
B33: =DPA!B50 -> 5.1.02.01.01.0027 | C33: =DPA!C50 -> Belanja Alat/Bahan untuk Kegiatan Kantor-Benda Pos | K33: =DPA!S50 -> 150000 | M33: =K33 -> 150000
D34: =DPA!D51 -> - | E34: =DPA!E51 -> Materai Spesifikasi: Materai 10.000 | K34: =DPA!S51 -> 150000 | M34: =K34 -> 150000
B36: =DPA!B53 -> 5.1.02.04 | C36: =DPA!C53 -> Belanja Perjalanan Dinas | K36: =DPA!S53 -> 31208000 | M36: =K36 -> 31208000
B37: =DPA!B54 -> 5.1.02.04.01 | C37: =DPA!C54 -> Belanja Perjalanan Dinas Dalam Negeri | D37: =DPA!D54 | E37: =DPA!E54 | K37: =DPA!S54 -> 31208000 | M37: =K37 -> 31208000
B38: =DPA!B55 -> 5.1.02.04.01.0001 | C38: =DPA!C55 -> Belanja Perjalanan Dinas Biasa | D38: =DPA!D55 | E38: =DPA!E55 | K38: =DPA!S55 -> 31208000 | M38: =K38 -> 31208000
D39: =DPA!D56 -> - | E39: =DPA!E56 -> Penginapan Dalam Negeri di- D.K.I. JAKARTA Spesifikasi: PEJABAT ESELON III / GOLONGAN IV | K39: =DPA!S56 -> 7936000 | M39: =K39 -> 7936000
D40: =DPA!D57 -> - | E40: =DPA!E57 -> Taxi dari/ke Bandara - Perjalanan Dinas Dalam Negeri Spesifikasi: BALI | K40: =DPA!S57 -> 1816000 | M40: =K40 -> 1816000
D41: =DPA!D58 -> - | E41: =DPA!E58 -> Taxi dari/ke Bandara - Perjalanan Dinas Dalam Negeri Spesifikasi: D.K.I. JAKARTA | K41: =DPA!S58 -> 2048000 | M41: =K41 -> 2048000
D42: =DPA!D59 -> - | E42: =DPA!E59 -> Satuan Biaya Tiket Dalam Negeri Spesifikasi : Denpasar - Jakarta | K42: =DPA!S59 -> 13048000 | M42: =K42 -> 13048000
D43: =DPA!D60 -> - | E43: =DPA!E60 -> Uang Harian Perjalanan Dinas Luar Kota/Luar Daerah Spesifikasi: D.K.I. JAKARTA | K43: =DPA!S60 -> 6360000 | M43: =K43 -> 6360000
B45: =DPA!B62 -> 5.2 | C45: =DPA!C62 -> Belanja Modal | K45: =DPA!S62 -> 61372400 | M45: =K45 -> 61372400
B46: =DPA!B63 -> 5.2.02 | C46: =DPA!C63 -> Belanja Modal Perapatan dan Mesin | K46: =DPA!S63 -> 61372400 | M46: =K46 -> 61372400
B47: =DPA!B64 -> 5.2.02.05 | C47: =DPA!C64 -> Belanja Modal Alat Kantor dan Rumah Tangga | K47: =DPA!S64 -> 61372400 | M47: =K47 -> 61372400
B48: =DPA!B65 -> 5.2.02.05.001 | C48: =DPA!C65 -> Belanja Modal Alat Kantor | K48: =DPA!S65 -> 34347600 | M48: =K48 -> 34347600
...

Sheet Agustus
B1: LAPORAN REALISASI FISIK DAN KEUANGAN
B2: APBD PROVINSI BALI TAHUN 2017
B4: SKPD | D4: : | M4: PROGRAM
B5: SUB UNIT KERJA | D5: : | M5: KEGIATAN
B6: SUB BAGIAN | D6: : | M6: PPTK
B7: STATUS | D7: :
R8: Fn:C\Pramana\12PemelLGK.xls
B9: KODE REKENING | C9: URAIAN BELANJA | F9: RENCANA KEGIATAN | L9: PELAKSANAAN KEGIATAN | T9: SALDO
F10: VOL | G10: SAT | H10: LOKASI | I10: JML PAKET | K10: ANGGARAN | L10: KONTRAK SWAKELOLA | M10: SISA ANGGARAN | N10: PROGRES
N11: FISIK | Q11: KEUANGAN
N12: RENC | O12: REAL | P12: DEV | Q12: RENC | R12: REAL Rp. | S12: %
B13: a | C13: b | F13: c | G13: d | H13: e | I13: f | K13: g | L13: h | M13: i | N13: j | O13: k | P13: l | Q13: m | R13: n | S13: o | T13: p
B14: =DPA!B31 -> 5 | C14: =DPA!C31 -> BELANJA DAERAH | K14: =DPA!S31 -> 94371800 | M14: =K14 -> 94371800
B15: =DPA!B32 -> 5.1 | C15: =DPA!C32 -> BELANJA OPERASI | K15: =DPA!S32 -> 32999400 | M15: =K15 -> 32999400
B17: =DPA!B34 -> 5.2.2. | C17: =DPA!C34 -> Belanja Barang dan Jasa | K17: =DPA!S34 -> 32999400 | M17: =K17 -> 32999400
B19: =DPA!B36 -> 5.2.2.01 | C19: =DPA!C36 -> Belanja Bahan Pakai Habis | K19: =DPA!S36 -> 1791400 | M19: =K19 -> 1791400
B21: =DPA!B38 -> 5.1.02.01.01.0024 | C21: =DPA!C38 -> Belanja Alat/Bahan untuk Kegiatan Kantor-Alat Tulis Kantor | K21: =DPA!S38 -> 656000 | M21: =K21 -> 656000
D22: =DPA!D39 -> - | E22: =DPA!E39 -> Alat Tulis Kantor Spesifikasi : Stof Map Folio | K22: =DPA!S39 -> 330000 | M22: =K22 -> 330000
D23: =DPA!D40 -> - | E23: =DPA!E40 -> Alat Tulis Kantor Spesifikasi : Trigonal Clip No. 5 Atom | K23: =DPA!S40 -> 66000 | M23: =K23 -> 66000
D24: =DPA!D41 -> - | E24: =DPA!E41 -> Alat Tulis Kantor Spesifikasi : Box File Jumbo Bantex | K24: =DPA!S41 -> 260000 | M24: =K24 -> 260000
K25: =DPA!S42 | M25: =K25
B26: =DPA!B43 -> 5.1.02.01.01.0025 | C26: =DPA!C43 -> Belanja Alat/Bahan untuk Kegiatan Kantor- Kertas dan Cover | K26: =DPA!S43 -> 441400 | M26: =K26 -> 441400
D27: =DPA!D44 -> - | E27: =DPA!E44 -> Kertas dan Cover Spesifikasi : Kertas HVS A4 70 gr | K27: =DPA!S44 -> 164800 | M27: =K27 -> 164800
D28: =DPA!D45 -> - | E28: =DPA!E45 -> Kertas dan Cover Spesifikasi : Kertas HVS F4 70 gr | K28: =DPA!S45 -> 276600 | M28: =K28 -> 276600
B30: =DPA!B47 -> 5.1.02.01.01.0026 | C30: =DPA!C47 -> Belanja Alat/Bahan untuk Kegiatan Kantor- Bahan Cetak | K30: =DPA!S47 -> 544000 | M30: =K30 -> 544000
D31: =DPA!D48 -> - | E31: =DPA!E48 -> Foto Copy Spesifikasi : Foto copy Hitam Putih-HVS A4/F4 | K31: =DPA!S48 -> 544000 | M31: =K31 -> 544000
B33: =DPA!B50 -> 5.1.02.01.01.0027 | C33: =DPA!C50 -> Belanja Alat/Bahan untuk Kegiatan Kantor-Benda Pos | K33: =DPA!S50 -> 150000 | M33: =K33 -> 150000
